<?xml version="1.0" ?>
<!-- =================================================================================== -->
<!-- |    This document was autogenerated by xacro from ur5e_bhand.xacro               | -->
<!-- |    EDITING THIS FILE BY HAND IS NOT RECOMMENDED                                 | -->
<!-- =================================================================================== -->
<robot name="ur5e_bhand">
  <gazebo>
    <plugin filename="libgazebo_ros_control.so" name="ros_control">
      <!--robotNamespace>/</robotNamespace-->
      <!--robotSimType>gazebo_ros_control/DefaultRobotHWSim</robotSimType-->
    </plugin>
    <!--
    <plugin name="gazebo_ros_power_monitor_controller" filename="libgazebo_ros_power_monitor.so">
      <alwaysOn>true</alwaysOn>
      <updateRate>1.0</updateRate>
      <timeout>5</timeout>
      <powerStateTopic>power_state</powerStateTopic>
      <powerStateRate>10.0</powerStateRate>
      <fullChargeCapacity>87.78</fullChargeCapacity>     
      <dischargeRate>-474</dischargeRate>
      <chargeRate>525</chargeRate>
      <dischargeVoltage>15.52</dischargeVoltage>
      <chargeVoltage>16.41</chargeVoltage>
    </plugin>
-->
  </gazebo>
  <!-- Create the link of the hemisphere -->
  <!--property name="shoulder_height" value="0.089159" /-->
  <!--property name="shoulder_offset" value="0.13585" /-->
  <!-- shoulder_offset - elbow_offset + wrist_1_length = 0.10915 -->
  <!--property name="upper_arm_length" value="0.42500" /-->
  <!--property name="elbow_offset" value="0.1197" /-->
  <!-- CAD measured -->
  <!--property name="forearm_length" value="0.39225" /-->
  <!--property name="wrist_1_length" value="0.093" /-->
  <!-- CAD measured -->
  <!--property name="wrist_2_length" value="0.09465" /-->
  <!-- In CAD this distance is 0.930, but in the spec it is 0.09465 -->
  <!--property name="wrist_3_length" value="0.0823" /-->
  <!-- manually measured -->
  <link name="ur5_base_link">
    <visual>
      <geometry>
        <mesh filename="./ur5e/meshes/visual/base.dae"/>
      </geometry>
      <material name="LightGrey">
        <color rgba="0.7 0.7 0.7 1.0"/>
      </material>
    </visual>
    <collision>
      <geometry>
        <mesh filename="./ur5e/meshes/collision/base.stl"/>
      </geometry>
    </collision>
    <inertial>
      <mass value="4.0"/>
      <origin rpy="0 0 0" xyz="0.0 0.0 0.0"/>
      <inertia ixx="0.00443333156" ixy="0.0" ixz="0.0" iyy="0.00443333156" iyz="0.0" izz="0.0072"/>
    </inertial>
  </link>
  <joint name="ur5_shoulder_pan_joint" type="revolute">
    <parent link="ur5_base_link"/>
    <child link="ur5_shoulder_link"/>
    <origin rpy="0.0 0.0 3.141592653589793" xyz="0.0 0.0 0.163"/>
    <axis xyz="0 0 1"/>
    <limit effort="150.0" lower="-6.283185307179586" upper="6.283185307179586" velocity="3.14"/>
    <dynamics damping="0.0" friction="0.0"/>
  </joint>
  <link name="ur5_shoulder_link">
    <visual>
      <geometry>
        <mesh filename="./ur5e/meshes/visual/shoulder.dae"/>
      </geometry>
      <material name="LightGrey">
        <color rgba="0.7 0.7 0.7 1.0"/>
      </material>
    </visual>
    <collision>
      <geometry>
        <mesh filename="./ur5e/meshes/collision/shoulder.stl"/>
      </geometry>
    </collision>
    <inertial>
      <mass value="3.7"/>
      <origin rpy="0 0 0" xyz="0.0 0.0 0.0"/>
      <inertia ixx="0.010267495893" ixy="0.0" ixz="0.0" iyy="0.010267495893" iyz="0.0" izz="0.00666"/>
    </inertial>
  </link>
  <joint name="ur5_shoulder_lift_joint" type="revolute">
    <parent link="ur5_shoulder_link"/>
    <child link="ur5_upper_arm_link"/>
    <origin rpy="0.0 1.5707963267948966 0.0" xyz="0.0 0.138 0.0"/>
    <axis xyz="0 1 0"/>
    <limit effort="150.0" lower="-6.283185307179586" upper="6.283185307179586" velocity="3.14"/>
    <dynamics damping="0.0" friction="0.0"/>
  </joint>
  <link name="ur5_upper_arm_link">
    <visual>
      <geometry>
        <mesh filename="./ur5e/meshes/visual/upperarm.dae"/>
      </geometry>
      <material name="LightGrey">
        <color rgba="0.7 0.7 0.7 1.0"/>
      </material>
    </visual>
    <collision>
      <geometry>
        <mesh filename="./ur5e/meshes/collision/upperarm.stl"/>
      </geometry>
    </collision>
    <inertial>
      <mass value="8.393"/>
      <origin rpy="0 0 0" xyz="0.0 0.0 0.2125"/>
      <inertia ixx="0.1338857818623325" ixy="0.0" ixz="0.0" iyy="0.1338857818623325" iyz="0.0" izz="0.0151074"/>
    </inertial>
  </link>
  <joint name="ur5_elbow_joint" type="revolute">
    <parent link="ur5_upper_arm_link"/>
    <child link="ur5_forearm_link"/>
    <origin rpy="0.0 0.0 0.0" xyz="0.0 -0.131 0.425"/>
    <axis xyz="0 1 0"/>
    <limit effort="150.0" lower="-3.141592653589793" upper="3.141592653589793" velocity="3.14"/>
    <dynamics damping="0.0" friction="0.0"/>
  </joint>
  <link name="ur5_forearm_link">
    <visual>
      <geometry>
        <mesh filename="./ur5e/meshes/visual/forearm.dae"/>
      </geometry>
      <material name="LightGrey">
        <color rgba="0.7 0.7 0.7 1.0"/>
      </material>
    </visual>
    <collision>
      <geometry>
        <mesh filename="./ur5e/meshes/collision/forearm.stl"/>
      </geometry>
    </collision>
    <inertial>
      <mass value="2.275"/>
      <origin rpy="0 0 0" xyz="0.0 0.0 0.196"/>
      <inertia ixx="0.031179620861480004" ixy="0.0" ixz="0.0" iyy="0.031179620861480004" iyz="0.0" izz="0.004095"/>
    </inertial>
  </link>
  <joint name="ur5_wrist_1_joint" type="revolute">
    <parent link="ur5_forearm_link"/>
    <child link="ur5_wrist_1_link"/>
    <origin rpy="0.0 1.5707963267948966 0.0" xyz="0.0 0.0 0.392"/>
    <axis xyz="0 1 0"/>
    <limit effort="28.0" lower="-6.283185307179586" upper="6.283185307179586" velocity="6.28"/>
    <dynamics damping="0.0" friction="0.0"/>
  </joint>
  <link name="ur5_wrist_1_link">
    <visual>
      <geometry>
        <mesh filename="./ur5e/meshes/visual/wrist1.dae"/>
      </geometry>
      <material name="LightGrey">
        <color rgba="0.7 0.7 0.7 1.0"/>
      </material>
    </visual>
    <collision>
      <geometry>
        <mesh filename="./ur5e/meshes/collision/wrist1.stl"/>
      </geometry>
    </collision>
    <inertial>
      <mass value="1.219"/>
      <origin rpy="0 0 0" xyz="0.0 0.127 0.0"/>
      <inertia ixx="0.0025598989760400002" ixy="0.0" ixz="0.0" iyy="0.0025598989760400002" iyz="0.0" izz="0.0021942"/>
    </inertial>
  </link>
  <joint name="ur5_wrist_2_joint" type="revolute">
    <parent link="ur5_wrist_1_link"/>
    <child link="ur5_wrist_2_link"/>
    <origin rpy="0.0 0.0 0.0" xyz="0.0 0.127 0.0"/>
    <axis xyz="0 0 1"/>
    <limit effort="28.0" lower="-6.283185307179586" upper="6.283185307179586" velocity="6.28"/>
    <dynamics damping="0.0" friction="0.0"/>
  </joint>
  <link name="ur5_wrist_2_link">
    <visual>
      <geometry>
        <mesh filename="./ur5e/meshes/visual/wrist2.dae"/>
      </geometry>
      <material name="LightGrey">
        <color rgba="0.7 0.7 0.7 1.0"/>
      </material>
    </visual>
    <collision>
      <geometry>
        <mesh filename="./ur5e/meshes/collision/wrist2.stl"/>
      </geometry>
    </collision>
    <inertial>
      <mass value="1.219"/>
      <origin rpy="0 0 0" xyz="0.0 0.0 0.1"/>
      <inertia ixx="0.0025598989760400002" ixy="0.0" ixz="0.0" iyy="0.0025598989760400002" iyz="0.0" izz="0.0021942"/>
    </inertial>
  </link>
  <joint name="ur5_wrist_3_joint" type="revolute">
    <parent link="ur5_wrist_2_link"/>
    <child link="ur5_wrist_3_link"/>
    <origin rpy="0.0 0.0 0.0" xyz="0.0 0.0 0.1"/>
    <axis xyz="0 1 0"/>
    <limit effort="28.0" lower="-6.283185307179586" upper="6.283185307179586" velocity="6.28"/>
    <dynamics damping="0.0" friction="0.0"/>
  </joint>
  <link name="ur5_wrist_3_link">
    <visual>
      <geometry>
        <mesh filename="./ur5e/meshes/visual/wrist3.dae"/>
      </geometry>
      <material name="LightGrey">
        <color rgba="0.7 0.7 0.7 1.0"/>
      </material>
    </visual>
    <collision>
      <geometry>
        <mesh filename="./ur5e/meshes/collision/wrist3.stl"/>
      </geometry>
    </collision>
    <inertial>
      <mass value="0.1879"/>
      <origin rpy="1.5707963267948966 0 0" xyz="0.0 0.0771 0.0"/>
      <inertia ixx="9.890410052167731e-05" ixy="0.0" ixz="0.0" iyy="9.890410052167731e-05" iyz="0.0" izz="0.0001321171875"/>
    </inertial>
  </link>
  <joint name="ur5_ee_fixed_joint" type="fixed">
    <parent link="ur5_wrist_3_link"/>
    <child link="ur5_ee_link"/>
    <origin rpy="0.0 0.0 1.5707963267948966" xyz="0.0 0.1 0.0"/>
  </joint>
  <link name="ur5_ee_link">
    <collision>
      <geometry>
        <box size="0.01 0.01 0.01"/>
      </geometry>
      <origin rpy="0 0 0" xyz="-0.01 0 0"/>
    </collision>
  </link>
  <transmission name="ur5_shoulder_pan_trans">
    <type>transmission_interface/SimpleTransmission</type>
    <joint name="ur5_shoulder_pan_joint">
      <hardwareInterface>hardware_interface/PositionJointInterface</hardwareInterface>
    </joint>
    <actuator name="ur5_shoulder_pan_motor">
      <mechanicalReduction>1</mechanicalReduction>
    </actuator>
  </transmission>
  <transmission name="ur5_shoulder_lift_trans">
    <type>transmission_interface/SimpleTransmission</type>
    <joint name="ur5_shoulder_lift_joint">
      <hardwareInterface>hardware_interface/PositionJointInterface</hardwareInterface>
    </joint>
    <actuator name="ur5_shoulder_lift_motor">
      <mechanicalReduction>1</mechanicalReduction>
    </actuator>
  </transmission>
  <transmission name="ur5_elbow_trans">
    <type>transmission_interface/SimpleTransmission</type>
    <joint name="ur5_elbow_joint">
      <hardwareInterface>hardware_interface/PositionJointInterface</hardwareInterface>
    </joint>
    <actuator name="ur5_elbow_motor">
      <mechanicalReduction>1</mechanicalReduction>
    </actuator>
  </transmission>
  <transmission name="ur5_wrist_1_trans">
    <type>transmission_interface/SimpleTransmission</type>
    <joint name="ur5_wrist_1_joint">
      <hardwareInterface>hardware_interface/PositionJointInterface</hardwareInterface>
    </joint>
    <actuator name="ur5_wrist_1_motor">
      <mechanicalReduction>1</mechanicalReduction>
    </actuator>
  </transmission>
  <transmission name="ur5_wrist_2_trans">
    <type>transmission_interface/SimpleTransmission</type>
    <joint name="ur5_wrist_2_joint">
      <hardwareInterface>hardware_interface/PositionJointInterface</hardwareInterface>
    </joint>
    <actuator name="ur5_wrist_2_motor">
      <mechanicalReduction>1</mechanicalReduction>
    </actuator>
  </transmission>
  <transmission name="ur5_wrist_3_trans">
    <type>transmission_interface/SimpleTransmission</type>
    <joint name="ur5_wrist_3_joint">
      <hardwareInterface>hardware_interface/PositionJointInterface</hardwareInterface>
    </joint>
    <actuator name="ur5_wrist_3_motor">
      <mechanicalReduction>1</mechanicalReduction>
    </actuator>
  </transmission>
  <gazebo reference="ur5_shoulder_link">
    <selfCollide>true</selfCollide>
  </gazebo>
  <gazebo reference="ur5_upper_arm_link">
    <selfCollide>true</selfCollide>
  </gazebo>
  <gazebo reference="ur5_forearm_link">
    <selfCollide>true</selfCollide>
  </gazebo>
  <gazebo reference="ur5_wrist_1_link">
    <selfCollide>true</selfCollide>
  </gazebo>
  <gazebo reference="ur5_wrist_3_link">
    <selfCollide>true</selfCollide>
  </gazebo>
  <gazebo reference="ur5_wrist_2_link">
    <selfCollide>true</selfCollide>
  </gazebo>
  <gazebo reference="ur5_ee_link">
    <selfCollide>true</selfCollide>
  </gazebo>
  <!-- ROS base_link to UR 'Base' Coordinates transform -->
  <link name="ur5_base"/>
  <joint name="ur5_base_link-base_fixed_joint" type="fixed">
    <!-- NOTE: this rotation is only needed as long as base_link itself is
                 not corrected wrt the real robot (ie: rotated over 180
                 degrees)
      -->
    <origin rpy="0 0 -3.141592653589793" xyz="0 0 0"/>
    <parent link="ur5_base_link"/>
    <child link="ur5_base"/>
  </joint>
  <!-- Frame coincident with all-zeros TCP on UR controller -->
  <link name="ur5_tool0"/>
  <joint name="ur5_wrist_3_link-tool0_fixed_joint" type="fixed">
    <origin rpy="-1.5707963267948966 0 0" xyz="0 0.1 0"/>
    <parent link="ur5_wrist_3_link"/>
    <child link="ur5_tool0"/>
  </joint>
  <link name="world"/>
  <joint name="world_joint" type="fixed">
    <parent link="world"/>
    <child link="ur5_base_link"/>
    <origin rpy="0.0 0.0 0.0" xyz="0.0 0.0 0.0"/>
  </joint>
  <joint name="ur5_bhand" type="fixed">
    <parent link="ur5_tool0"/>
    <child link="hand_base_link"/>
    <origin rpy="0 0 0" xyz="0 0 0"/>
  </joint>
  <link name="hand_base_link"/>
  <joint name="bh_base_joint" type="fixed">
    <origin rpy="0 0 0" xyz="0 0 0"/>
    <parent link="hand_base_link"/>
    <child link="bh_base_link"/>
  </joint>
  <!-- HAND BASE_LINK (RED) -->
  <link name="bh_base_link">
    <inertial>
      <mass value="3.0"/>
      <origin xyz="0 0 0"/>
      <inertia ixx="1.0" ixy="0.0" ixz="0.0" iyy="1.0" iyz="0.0" izz="1.0"/>
    </inertial>
    <visual>
      <origin rpy="0 0 0" xyz="0 0 0"/>
      <geometry>
        <mesh filename="./bhand/meshes/palm_282.dae"/>
      </geometry>
      <material name="Grey">
        <color rgba="0.75 0.75 0.75 1.0"/>
      </material>
    </visual>
    <collision>
      <origin rpy="0 0 0 " xyz="0 0 0"/>
      <geometry>
        <mesh filename="./bhand/meshes/palm_282.dae"/>
      </geometry>
      <contact_coefficients kd="1.0" kp="1000.0" mu="0"/>
    </collision>
  </link>
  <!-- finger 3 -->
  <!-- finger 31 link -->
  <link name="bh_finger_31_link">
    <inertial>
      <mass value="0.1"/>
      <origin rpy="0 0 0" xyz="-0.046 0 0"/>
      <inertia ixx="0.01" ixy="0" ixz="0" iyy="0.01" iyz="0" izz="0.01"/>
    </inertial>
    <visual>
      <origin rpy="0 0 0" xyz="-0.04 0 0"/>
      <geometry>
        <mesh filename="./bhand/meshes/knuckle_fixed.dae"/>
      </geometry>
      <material name="Black"/>
    </visual>
    <collision>
      <origin rpy="0 0 0" xyz="-0.04 0 0"/>
      <geometry>
        <mesh filename="./bhand/meshes/knuckle_fixed.dae"/>
      </geometry>
      <contact_coefficients kd="1.0" kp="1000.0" mu="0"/>
    </collision>
  </link>
  <!-- joint between BH_palm_link and BH_finger_31_link -->
  <!-- finger3 is the center finger and is fixed -->
  <joint name="bh_j31_joint" type="fixed">
    <parent link="bh_base_link"/>
    <child link="bh_finger_31_link"/>
    <origin rpy="0 0 -1.570796327" xyz="0 0 0.0252"/>
  </joint>
  <!-- finger 32 link -->
  <link name="bh_finger_32_link">
    <inertial>
      <mass value="0.1"/>
      <origin rpy="0 0 0" xyz="0 0 0"/>
      <inertia ixx="0.01" ixy="0" ixz="0" iyy="0.01" iyz="0" izz="0.01"/>
    </inertial>
    <visual>
      <origin rpy="0 0 0" xyz="0 0 0"/>
      <geometry>
        <mesh filename="./bhand/meshes/finger.dae"/>
      </geometry>
      <material name="Blue"/>
    </visual>
    <collision>
      <origin rpy="0 0 0" xyz="0 0 0"/>
      <geometry>
        <mesh filename="./bhand/meshes/finger.dae"/>
      </geometry>
      <contact_coefficients kd="1.0" kp="1000.0" mu="0"/>
    </collision>
  </link>
  <!-- joint between BH_finger_31_link and BH_finger_32_link -->
  <joint name="bh_j32_joint" type="revolute">
    <parent link="bh_finger_31_link"/>
    <child link="bh_finger_32_link"/>
    <origin rpy="1.5708 -8.8281E-17 0" xyz="-0.05 0 0.0339"/>
    <axis xyz="0 0 -1"/>
    <limit effort="30.0" lower="0.0" upper="2.44" velocity="2.0"/>
    <dynamics damping="100.0" friction="1.0"/>
  </joint>
  <transmission name="bh_j32_transmission">
    <type>transmission_interface/SimpleTransmission</type>
    <joint name="bh_j32_joint">
      <hardwareInterface>PositionJointInterface</hardwareInterface>
    </joint>
    <actuator name="bh_j32">
      <hardwareInterface>PositionJointInterface</hardwareInterface>
      <mechanicalReduction>1</mechanicalReduction>
      <motorTorqueConstant>1</motorTorqueConstant>
    </actuator>
  </transmission>
  <!-- finger 33 link -->
  <link name="bh_finger_33_link">
    <inertial>
      <mass value="0.1"/>
      <origin rpy="0 0 0" xyz="0 0 0"/>
      <inertia ixx="0.01" ixy="0" ixz="0" iyy="0.01" iyz="0" izz="0.01"/>
    </inertial>
    <visual>
      <origin rpy="0 0 0" xyz="0 0 0"/>
      <geometry>
        <mesh filename="./bhand/meshes/finger_tip.dae"/>
      </geometry>
      <material name="Blue"/>
    </visual>
    <collision>
      <origin rpy="0 0 0" xyz="0 0 0"/>
      <geometry>
        <mesh filename="./bhand/meshes/finger_tip.dae"/>
      </geometry>
      <contact_coefficients kd="1.0" kp="1000.0" mu="0"/>
    </collision>
  </link>
  <!-- joint between BH_finger_32_link and BH_finger_33_link -->
  <joint name="bh_j33_joint" type="revolute">
    <parent link="bh_finger_32_link"/>
    <child link="bh_finger_33_link"/>
    <origin rpy="0 0 0" xyz="-0.069936 0.003 0"/>
    <axis xyz="0 0 -1"/>
    <mimic joint="bh_j32_joint" multiplier="0.3442622950819672"/>
    <limit effort="30.0" lower="0.0" upper="0.84" velocity="2.0"/>
    <dynamics damping="100.0" friction="1.0"/>
  </joint>
  <transmission name="bh_j33_transmission">
    <type>transmission_interface/SimpleTransmission</type>
    <joint name="bh_j33_joint">
      <hardwareInterface>PositionJointInterface</hardwareInterface>
    </joint>
    <actuator name="bh_j33">
      <hardwareInterface>PositionJointInterface</hardwareInterface>
      <mechanicalReduction>1</mechanicalReduction>
      <motorTorqueConstant>1</motorTorqueConstant>
    </actuator>
  </transmission>
  <!-- finger 1 -->
  <!-- finger 11 link -->
  <link name="bh_finger_11_link">
    <inertial>
      <mass value="0.1"/>
      <origin rpy="0 0 0" xyz="-0.046 0 0"/>
      <inertia ixx="0.01" ixy="0" ixz="0" iyy="0.01" iyz="0" izz="0.01"/>
    </inertial>
    <visual>
      <origin rpy="0 0 0" xyz="0 0 0"/>
      <geometry>
        <mesh filename="./bhand/meshes/knuckle.dae"/>
      </geometry>
      <material name="Green"/>
    </visual>
    <collision>
      <origin rpy="0 0 0" xyz="0 0 0"/>
      <geometry>
        <mesh filename="./bhand/meshes/knuckle.dae"/>
      </geometry>
    </collision>
  </link>
  <!-- joint between BH_palm_link and BH_finger_11_link -->
  <joint name="bh_j11_joint" type="revolute">
    <parent link="bh_base_link"/>
    <child link="bh_finger_11_link"/>
    <origin rpy="0 0 1.5708" xyz="-0.025 0 0.0252"/>
    <axis xyz="0 0 -1"/>
    <limit effort="30.0" lower="0" upper="3.1416" velocity="2.0"/>
    <dynamics damping="100.0" friction="1.0"/>
  </joint>
  <transmission name="bh_j11_transmission">
    <type>transmission_interface/SimpleTransmission</type>
    <joint name="bh_j11_joint">
      <hardwareInterface>PositionJointInterface</hardwareInterface>
    </joint>
    <actuator name="bh_j11">
      <hardwareInterface>PositionJointInterface</hardwareInterface>
      <mechanicalReduction>1</mechanicalReduction>
      <motorTorqueConstant>1</motorTorqueConstant>
    </actuator>
  </transmission>
  <!-- finger 12 link -->
  <link name="bh_finger_12_link">
    <inertial>
      <mass value="0.1"/>
      <origin rpy="0 0 0" xyz="0 0 0"/>
      <inertia ixx="0.01" ixy="0" ixz="0" iyy="0.01" iyz="0" izz="0.01"/>
    </inertial>
    <visual>
      <origin rpy="0 0 0" xyz="0 0 0"/>
      <geometry>
        <mesh filename="./bhand/meshes/finger.dae"/>
      </geometry>
      <material name="Blue"/>
    </visual>
    <collision>
      <origin rpy="0 0 0" xyz="0 0 0"/>
      <geometry>
        <mesh filename="./bhand/meshes/finger.dae"/>
      </geometry>
      <contact_coefficients kd="1.0" kp="1000.0" mu="0"/>
    </collision>
  </link>
  <!-- joint between BH_finger_11_link and BH_finger_12_link -->
  <joint name="bh_j12_joint" type="revolute">
    <parent link="bh_finger_11_link"/>
    <child link="bh_finger_12_link"/>
    <origin rpy="1.5708 0 0" xyz="-0.05 0 0.0339"/>
    <axis xyz="0 0 -1"/>
    <limit effort="30.0" lower="0.0" upper="2.44" velocity="2.0"/>
    <dynamics damping="100.0" friction="1.0"/>
  </joint>
  <transmission name="bh_j12_transmission">
    <type>transmission_interface/SimpleTransmission</type>
    <joint name="bh_j12_joint">
      <hardwareInterface>PositionJointInterface</hardwareInterface>
    </joint>
    <actuator name="bh_j12">
      <hardwareInterface>PositionJointInterface</hardwareInterface>
      <mechanicalReduction>1</mechanicalReduction>
      <motorTorqueConstant>1</motorTorqueConstant>
    </actuator>
  </transmission>
  <!-- finger 13 link -->
  <link name="bh_finger_13_link">
    <inertial>
      <mass value="0.1"/>
      <origin rpy="0 0 0" xyz="0 0 0"/>
      <inertia ixx="0.01" ixy="0" ixz="0" iyy="0.01" iyz="0" izz="0.01"/>
    </inertial>
    <visual>
      <origin rpy="0 0 0" xyz="0 0 0"/>
      <geometry>
        <mesh filename="./bhand/meshes/finger_tip.dae"/>
      </geometry>
      <material name="Blue"/>
    </visual>
    <collision>
      <origin rpy="0 0 0" xyz="0 0 0"/>
      <geometry>
        <mesh filename="./bhand/meshes/finger_tip.dae"/>
      </geometry>
      <contact_coefficients kd="1.0" kp="1000.0" mu="0"/>
    </collision>
  </link>
  <!-- joint between BH_finger_12_link and BH_finger_13_link -->
  <joint name="bh_j13_joint" type="revolute">
    <parent link="bh_finger_12_link"/>
    <child link="bh_finger_13_link"/>
    <origin rpy="0 0 0" xyz="-0.069936 0.003 0"/>
    <axis xyz="0 0 -1"/>
    <mimic joint="bh_j12_joint" multiplier="0.3442622950819672"/>
    <limit effort="30.0" lower="0.0" upper="0.84" velocity="2.0"/>
    <dynamics damping="100.0" friction="1.0"/>
  </joint>
  <transmission name="bh_j13_transmission">
    <type>transmission_interface/SimpleTransmission</type>
    <joint name="bh_j13_joint">
      <hardwareInterface>PositionJointInterface</hardwareInterface>
    </joint>
    <actuator name="bh_j13">
      <hardwareInterface>PositionJointInterface</hardwareInterface>
      <mechanicalReduction>1</mechanicalReduction>
      <motorTorqueConstant>1</motorTorqueConstant>
    </actuator>
  </transmission>
  <!-- finger 2 -->
  <!-- finger 21 link -->
  <link name="bh_finger_21_link">
    <inertial>
      <mass value="0.1"/>
      <origin rpy="0 0 0" xyz="-0.046 0 0"/>
      <inertia ixx="0.01" ixy="0" ixz="0" iyy="0.01" iyz="0" izz="0.01"/>
    </inertial>
    <visual>
      <origin rpy="0 0 0" xyz="0 0 0"/>
      <geometry>
        <mesh filename="./bhand/meshes/knuckle.dae"/>
      </geometry>
      <material name="Green"/>
    </visual>
    <collision>
      <origin rpy="0 0 0" xyz="0 0 0"/>
      <geometry>
        <mesh filename="./bhand/meshes/knuckle.dae"/>
      </geometry>
    </collision>
  </link>
  <!-- joint between BH_palm_link and BH_finger_21_link -->
  <joint name="bh_j21_joint" type="revolute">
    <parent link="bh_base_link"/>
    <child link="bh_finger_21_link"/>
    <origin rpy="0 0 1.5708" xyz="0.025 0 0.0252"/>
    <axis xyz="0 0 1"/>
    <mimic joint="bh_j11_joint" multiplier="1"/>
    <limit effort="30.0" lower="0" upper="3.1416" velocity="2.0"/>
    <dynamics damping="100.0" friction="1.0"/>
  </joint>
  <transmission name="bh_j21_transmission">
    <type>transmission_interface/SimpleTransmission</type>
    <joint name="bh_j21_joint">
      <hardwareInterface>PositionJointInterface</hardwareInterface>
    </joint>
    <actuator name="bh_j21">
      <hardwareInterface>PositionJointInterface</hardwareInterface>
      <mechanicalReduction>1</mechanicalReduction>
      <motorTorqueConstant>1</motorTorqueConstant>
    </actuator>
  </transmission>
  <!-- finger 12 link -->
  <link name="bh_finger_22_link">
    <inertial>
      <mass value="0.1"/>
      <origin rpy="0 0 0" xyz="0 0 0"/>
      <inertia ixx="0.01" ixy="0" ixz="0" iyy="0.01" iyz="0" izz="0.01"/>
    </inertial>
    <visual>
      <origin rpy="0 0 0" xyz="0 0 0"/>
      <geometry>
        <mesh filename="./bhand/meshes/finger.dae"/>
      </geometry>
      <material name="Blue"/>
    </visual>
    <collision>
      <origin rpy="0 0 0" xyz="0 0 0"/>
      <geometry>
        <mesh filename="./bhand/meshes/finger.dae"/>
      </geometry>
      <contact_coefficients kd="1.0" kp="1000.0" mu="0"/>
    </collision>
  </link>
  <!-- joint between BH_finger_21_link and BH_finger_22_link -->
  <joint name="bh_j22_joint" type="revolute">
    <parent link="bh_finger_21_link"/>
    <child link="bh_finger_22_link"/>
    <origin rpy="1.5708 -8.8281E-17 0" xyz="-0.05 0 0.0339"/>
    <axis xyz="0 0 -1"/>
    <limit effort="30.0" lower="0.0" upper="2.44" velocity="2.0"/>
    <dynamics damping="100.0" friction="1.0"/>
  </joint>
  <transmission name="bh_j22_transmission">
    <type>transmission_interface/SimpleTransmission</type>
    <joint name="bh_j22_joint">
      <hardwareInterface>PositionJointInterface</hardwareInterface>
    </joint>
    <actuator name="bh_j22">
      <hardwareInterface>PositionJointInterface</hardwareInterface>
      <mechanicalReduction>1</mechanicalReduction>
      <motorTorqueConstant>1</motorTorqueConstant>
    </actuator>
  </transmission>
  <!-- finger 23 link -->
  <link name="bh_finger_23_link">
    <inertial>
      <mass value="0.1"/>
      <origin rpy="0 0 0" xyz="0 0 0"/>
      <inertia ixx="0.01" ixy="0" ixz="0" iyy="0.01" iyz="0" izz="0.01"/>
    </inertial>
    <visual>
      <origin rpy="0 0 0" xyz="0 0 0"/>
      <geometry>
        <mesh filename="./bhand/meshes/finger_tip.dae"/>
      </geometry>
      <material name="Blue"/>
    </visual>
    <collision>
      <origin rpy="0 0 0" xyz="0 0 0"/>
      <geometry>
        <mesh filename="./bhand/meshes/finger_tip.dae"/>
      </geometry>
      <contact_coefficients kd="1.0" kp="1000.0" mu="0"/>
    </collision>
  </link>
  <!-- joint between BH_finger_22_link and BH_finger_23_link -->
  <joint name="bh_j23_joint" type="revolute">
    <parent link="bh_finger_22_link"/>
    <child link="bh_finger_23_link"/>
    <origin rpy="0 0 0" xyz="-0.069936 0.003 0"/>
    <axis xyz="0 0 -1"/>
    <mimic joint="bh_j22_joint" multiplier="0.3442622950819672"/>
    <limit effort="30.0" lower="0.0" upper="0.84" velocity="2.0"/>
    <dynamics damping="100.0" friction="1.0"/>
  </joint>
  <transmission name="bh_j23_transmission">
    <type>transmission_interface/SimpleTransmission</type>
    <joint name="bh_j23_joint">
      <hardwareInterface>PositionJointInterface</hardwareInterface>
    </joint>
    <actuator name="bh_j23">
      <hardwareInterface>PositionJointInterface</hardwareInterface>
      <mechanicalReduction>1</mechanicalReduction>
      <motorTorqueConstant>1</motorTorqueConstant>
    </actuator>
  </transmission>
  <!-- finger 23 link -->
  <link name="bh_finger_1_tip_link"/>
  <!-- joint between BH_finger_21_link and BH_finger_22_link -->
  <joint name="bh_j13_tip_joint" type="fixed">
    <parent link="bh_finger_13_link"/>
    <child link="bh_finger_1_tip_link"/>
    <origin rpy="0.76 1.57 1.57" xyz="-0.03 0.037 0"/>
  </joint>
  <!-- finger 23 link -->
  <link name="bh_finger_2_tip_link"/>
  <!-- joint between BH_finger_21_link and BH_finger_22_link -->
  <joint name="bh_j23_tip_joint" type="fixed">
    <parent link="bh_finger_23_link"/>
    <child link="bh_finger_2_tip_link"/>
    <origin rpy="0.76 1.57 1.57" xyz="-0.03 0.037 0"/>
  </joint>
  <!-- finger 23 link -->
  <link name="bh_finger_3_tip_link"/>
  <!-- joint between BH_finger_21_link and BH_finger_22_link -->
  <joint name="bh_j33_tip_joint" type="fixed">
    <parent link="bh_finger_33_link"/>
    <child link="bh_finger_3_tip_link"/>
    <origin rpy="0.76 1.57 1.57" xyz="-0.03 0.037 0"/>
  </joint>
  <!-- finger 23 link -->
  <link name="bh_palm_link"/>
  <!-- joint between BH_finger_21_link and BH_finger_22_link -->
  <joint name="bh_base_palm_joint" type="fixed">
    <parent link="bh_base_link"/>
    <child link="bh_palm_link"/>
    <origin rpy="0 0 0" xyz="0 0 0.06"/>
  </joint>
  <gazebo>
    <plugin filename="libgazebo_mimic_plugin.so" name="mimic_plugin">
      <joint>bh_j11_joint</joint>
      <mimicJoint>bh_j21_joint</mimicJoint>
      <multiplier>1</multiplier>
    </plugin>
  </gazebo>
  <gazebo>
    <plugin filename="libgazebo_mimic_plugin.so" name="mimic_plugin">
      <joint>bh_j12_joint</joint>
      <mimicJoint>bh_j13_joint</mimicJoint>
      <multiplier>0.344</multiplier>
    </plugin>
  </gazebo>
  <gazebo>
    <plugin filename="libgazebo_mimic_plugin.so" name="mimic_plugin">
      <joint>bh_j22_joint</joint>
      <mimicJoint>bh_j23_joint</mimicJoint>
      <multiplier>0.344</multiplier>
    </plugin>
  </gazebo>
  <gazebo>
    <plugin filename="libgazebo_mimic_plugin.so" name="mimic_plugin">
      <joint>bh_j32_joint</joint>
      <mimicJoint>bh_j33_joint</mimicJoint>
      <multiplier>0.344</multiplier>
    </plugin>
  </gazebo>
  <gazebo reference="bh_base_link">
    <material>Gazebo/White</material>
    <turnGravityOff>False</turnGravityOff>
  </gazebo>
  <gazebo reference="bh_finger_31_link">
    <material>Gazebo/Grey</material>
    <turnGravityOff>False</turnGravityOff>
  </gazebo>
  <gazebo reference="bh_finger_32_link">
    <material>Gazebo/Grey</material>
    <turnGravityOff>False</turnGravityOff>
  </gazebo>
  <gazebo reference="bh_finger_33_link">
    <material>Gazebo/Grey</material>
    <turnGravityOff>False</turnGravityOff>
  </gazebo>
  <gazebo reference="bh_finger_11_link">
    <material>Gazebo/Grey</material>
    <turnGravityOff>False</turnGravityOff>
  </gazebo>
  <gazebo reference="bh_finger_12_link">
    <material>Gazebo/Grey</material>
    <turnGravityOff>False</turnGravityOff>
  </gazebo>
  <gazebo reference="bh_finger_13_link">
    <material>Gazebo/Grey</material>
    <turnGravityOff>False</turnGravityOff>
  </gazebo>
  <gazebo reference="bh_finger_21_link">
    <material>Gazebo/Grey</material>
    <turnGravityOff>False</turnGravityOff>
  </gazebo>
  <gazebo reference="bh_finger_22_link">
    <material>Gazebo/Grey</material>
    <turnGravityOff>False</turnGravityOff>
  </gazebo>
  <gazebo reference="bh_finger_23_link">
    <material>Gazebo/Grey</material>
    <turnGravityOff>False</turnGravityOff>
  </gazebo>
</robot>

